{
 "cells": [
  {
   "cell_type": "code",
   "execution_count": 6,
   "id": "0a09fecd-f826-4817-928f-6241afccbe7d",
   "metadata": {},
   "outputs": [
    {
     "name": "stdout",
     "output_type": "stream",
     "text": [
      "Model: \"sequential_27\"\n",
      "_________________________________________________________________\n",
      " Layer (type)                Output Shape              Param #   \n",
      "=================================================================\n",
      " conv2d_54 (Conv2D)          (None, 68, 68, 64)        640       \n",
      "                                                                 \n",
      " activation_108 (Activation)  (None, 68, 68, 64)       0         \n",
      "                                                                 \n",
      " max_pooling2d_54 (MaxPoolin  (None, 34, 34, 64)       0         \n",
      " g2D)                                                            \n",
      "                                                                 \n",
      " conv2d_55 (Conv2D)          (None, 32, 32, 64)        36928     \n",
      "                                                                 \n",
      " activation_109 (Activation)  (None, 32, 32, 64)       0         \n",
      "                                                                 \n",
      " max_pooling2d_55 (MaxPoolin  (None, 16, 16, 64)       0         \n",
      " g2D)                                                            \n",
      "                                                                 \n",
      " conv2d_56 (Conv2D)          (None, 14, 14, 64)        36928     \n",
      "                                                                 \n",
      " activation_110 (Activation)  (None, 14, 14, 64)       0         \n",
      "                                                                 \n",
      " max_pooling2d_56 (MaxPoolin  (None, 7, 7, 64)         0         \n",
      " g2D)                                                            \n",
      "                                                                 \n",
      " flatten_27 (Flatten)        (None, 3136)              0         \n",
      "                                                                 \n",
      " dense_54 (Dense)            (None, 1)                 3137      \n",
      "                                                                 \n",
      " activation_111 (Activation)  (None, 1)                0         \n",
      "                                                                 \n",
      "=================================================================\n",
      "Total params: 77,633\n",
      "Trainable params: 77,633\n",
      "Non-trainable params: 0\n",
      "_________________________________________________________________\n"
     ]
    },
    {
     "ename": "ValueError",
     "evalue": "in user code:\n\n    File \"C:\\Users\\oscar\\anaconda3\\envs\\CleanMLEnv\\lib\\site-packages\\keras\\engine\\training.py\", line 2041, in predict_function  *\n        return step_function(self, iterator)\n    File \"C:\\Users\\oscar\\anaconda3\\envs\\CleanMLEnv\\lib\\site-packages\\keras\\engine\\training.py\", line 2027, in step_function  **\n        outputs = model.distribute_strategy.run(run_step, args=(data,))\n    File \"C:\\Users\\oscar\\anaconda3\\envs\\CleanMLEnv\\lib\\site-packages\\keras\\engine\\training.py\", line 2015, in run_step  **\n        outputs = model.predict_step(data)\n    File \"C:\\Users\\oscar\\anaconda3\\envs\\CleanMLEnv\\lib\\site-packages\\keras\\engine\\training.py\", line 1983, in predict_step\n        return self(x, training=False)\n    File \"C:\\Users\\oscar\\anaconda3\\envs\\CleanMLEnv\\lib\\site-packages\\keras\\utils\\traceback_utils.py\", line 70, in error_handler\n        raise e.with_traceback(filtered_tb) from None\n    File \"C:\\Users\\oscar\\anaconda3\\envs\\CleanMLEnv\\lib\\site-packages\\keras\\engine\\input_spec.py\", line 295, in assert_input_compatibility\n        raise ValueError(\n\n    ValueError: Input 0 of layer \"sequential_27\" is incompatible with the layer: expected shape=(None, 70, 70, 1), found shape=(None, 100, 100, 1)\n",
     "output_type": "error",
     "traceback": [
      "\u001b[1;31m---------------------------------------------------------------------------\u001b[0m",
      "\u001b[1;31mValueError\u001b[0m                                Traceback (most recent call last)",
      "Cell \u001b[1;32mIn[6], line 16\u001b[0m\n\u001b[0;32m     13\u001b[0m model\u001b[38;5;241m.\u001b[39msummary()  \u001b[38;5;66;03m# Verify the expected input shape\u001b[39;00m\n\u001b[0;32m     15\u001b[0m \u001b[38;5;66;03m# Perform prediction\u001b[39;00m\n\u001b[1;32m---> 16\u001b[0m prediction \u001b[38;5;241m=\u001b[39m \u001b[43mmodel\u001b[49m\u001b[38;5;241;43m.\u001b[39;49m\u001b[43mpredict\u001b[49m\u001b[43m(\u001b[49m\u001b[43m[\u001b[49m\u001b[43mprepare\u001b[49m\u001b[43m(\u001b[49m\u001b[38;5;124;43m'\u001b[39;49m\u001b[38;5;124;43mCat.jpg\u001b[39;49m\u001b[38;5;124;43m'\u001b[39;49m\u001b[43m)\u001b[49m\u001b[43m]\u001b[49m\u001b[43m)\u001b[49m\n\u001b[0;32m     17\u001b[0m \u001b[38;5;28mprint\u001b[39m(prediction)\n",
      "File \u001b[1;32m~\\anaconda3\\envs\\CleanMLEnv\\lib\\site-packages\\keras\\utils\\traceback_utils.py:70\u001b[0m, in \u001b[0;36mfilter_traceback.<locals>.error_handler\u001b[1;34m(*args, **kwargs)\u001b[0m\n\u001b[0;32m     67\u001b[0m     filtered_tb \u001b[38;5;241m=\u001b[39m _process_traceback_frames(e\u001b[38;5;241m.\u001b[39m__traceback__)\n\u001b[0;32m     68\u001b[0m     \u001b[38;5;66;03m# To get the full stack trace, call:\u001b[39;00m\n\u001b[0;32m     69\u001b[0m     \u001b[38;5;66;03m# `tf.debugging.disable_traceback_filtering()`\u001b[39;00m\n\u001b[1;32m---> 70\u001b[0m     \u001b[38;5;28;01mraise\u001b[39;00m e\u001b[38;5;241m.\u001b[39mwith_traceback(filtered_tb) \u001b[38;5;28;01mfrom\u001b[39;00m \u001b[38;5;28;01mNone\u001b[39;00m\n\u001b[0;32m     71\u001b[0m \u001b[38;5;28;01mfinally\u001b[39;00m:\n\u001b[0;32m     72\u001b[0m     \u001b[38;5;28;01mdel\u001b[39;00m filtered_tb\n",
      "File \u001b[1;32m~\\AppData\\Local\\Temp\\__autograph_generated_filer9s2soeq.py:15\u001b[0m, in \u001b[0;36mouter_factory.<locals>.inner_factory.<locals>.tf__predict_function\u001b[1;34m(iterator)\u001b[0m\n\u001b[0;32m     13\u001b[0m \u001b[38;5;28;01mtry\u001b[39;00m:\n\u001b[0;32m     14\u001b[0m     do_return \u001b[38;5;241m=\u001b[39m \u001b[38;5;28;01mTrue\u001b[39;00m\n\u001b[1;32m---> 15\u001b[0m     retval_ \u001b[38;5;241m=\u001b[39m ag__\u001b[38;5;241m.\u001b[39mconverted_call(ag__\u001b[38;5;241m.\u001b[39mld(step_function), (ag__\u001b[38;5;241m.\u001b[39mld(\u001b[38;5;28mself\u001b[39m), ag__\u001b[38;5;241m.\u001b[39mld(iterator)), \u001b[38;5;28;01mNone\u001b[39;00m, fscope)\n\u001b[0;32m     16\u001b[0m \u001b[38;5;28;01mexcept\u001b[39;00m:\n\u001b[0;32m     17\u001b[0m     do_return \u001b[38;5;241m=\u001b[39m \u001b[38;5;28;01mFalse\u001b[39;00m\n",
      "\u001b[1;31mValueError\u001b[0m: in user code:\n\n    File \"C:\\Users\\oscar\\anaconda3\\envs\\CleanMLEnv\\lib\\site-packages\\keras\\engine\\training.py\", line 2041, in predict_function  *\n        return step_function(self, iterator)\n    File \"C:\\Users\\oscar\\anaconda3\\envs\\CleanMLEnv\\lib\\site-packages\\keras\\engine\\training.py\", line 2027, in step_function  **\n        outputs = model.distribute_strategy.run(run_step, args=(data,))\n    File \"C:\\Users\\oscar\\anaconda3\\envs\\CleanMLEnv\\lib\\site-packages\\keras\\engine\\training.py\", line 2015, in run_step  **\n        outputs = model.predict_step(data)\n    File \"C:\\Users\\oscar\\anaconda3\\envs\\CleanMLEnv\\lib\\site-packages\\keras\\engine\\training.py\", line 1983, in predict_step\n        return self(x, training=False)\n    File \"C:\\Users\\oscar\\anaconda3\\envs\\CleanMLEnv\\lib\\site-packages\\keras\\utils\\traceback_utils.py\", line 70, in error_handler\n        raise e.with_traceback(filtered_tb) from None\n    File \"C:\\Users\\oscar\\anaconda3\\envs\\CleanMLEnv\\lib\\site-packages\\keras\\engine\\input_spec.py\", line 295, in assert_input_compatibility\n        raise ValueError(\n\n    ValueError: Input 0 of layer \"sequential_27\" is incompatible with the layer: expected shape=(None, 70, 70, 1), found shape=(None, 100, 100, 1)\n"
     ]
    }
   ],
   "source": [
    "import cv2\n",
    "import tensorflow as tf\n",
    "\n",
    "CATEGORIES = [\"Dog\", \"Cat\"]\n",
    "\n",
    "def prepare(filepath):\n",
    "    IMG_SIZE = 70 # Ensure this size matches your model's requirements\n",
    "    img_array = cv2.imread(filepath, cv2.IMREAD_GRAYSCALE)\n",
    "    new_array = cv2.resize(img_array, (IMG_SIZE, IMG_SIZE))\n",
    "    return new_array.reshape(-1, IMG_SIZE, IMG_SIZE, 1)\n",
    "\n",
    "model = tf.keras.models.load_model(\"64x3-CNN.model\")\n",
    "model.summary()  # Verify the expected input shape\n",
    "\n",
    "# Perform prediction\n",
    "prediction = model.predict([prepare('Cat.jpg')])\n",
    "print(prediction)"
   ]
  },
  {
   "cell_type": "code",
   "execution_count": 7,
   "id": "1257b6f8-f8e6-410b-ab9a-d4383f791f3b",
   "metadata": {},
   "outputs": [
    {
     "ename": "ValueError",
     "evalue": "in user code:\n\n    File \"C:\\Users\\oscar\\anaconda3\\envs\\CleanMLEnv\\lib\\site-packages\\keras\\engine\\training.py\", line 2041, in predict_function  *\n        return step_function(self, iterator)\n    File \"C:\\Users\\oscar\\anaconda3\\envs\\CleanMLEnv\\lib\\site-packages\\keras\\engine\\training.py\", line 2027, in step_function  **\n        outputs = model.distribute_strategy.run(run_step, args=(data,))\n    File \"C:\\Users\\oscar\\anaconda3\\envs\\CleanMLEnv\\lib\\site-packages\\keras\\engine\\training.py\", line 2015, in run_step  **\n        outputs = model.predict_step(data)\n    File \"C:\\Users\\oscar\\anaconda3\\envs\\CleanMLEnv\\lib\\site-packages\\keras\\engine\\training.py\", line 1983, in predict_step\n        return self(x, training=False)\n    File \"C:\\Users\\oscar\\anaconda3\\envs\\CleanMLEnv\\lib\\site-packages\\keras\\utils\\traceback_utils.py\", line 70, in error_handler\n        raise e.with_traceback(filtered_tb) from None\n    File \"C:\\Users\\oscar\\anaconda3\\envs\\CleanMLEnv\\lib\\site-packages\\keras\\engine\\input_spec.py\", line 295, in assert_input_compatibility\n        raise ValueError(\n\n    ValueError: Input 0 of layer \"sequential_27\" is incompatible with the layer: expected shape=(None, 70, 70, 1), found shape=(None, 100, 100, 1)\n",
     "output_type": "error",
     "traceback": [
      "\u001b[1;31m---------------------------------------------------------------------------\u001b[0m",
      "\u001b[1;31mValueError\u001b[0m                                Traceback (most recent call last)",
      "Cell \u001b[1;32mIn[7], line 1\u001b[0m\n\u001b[1;32m----> 1\u001b[0m prediction \u001b[38;5;241m=\u001b[39m \u001b[43mmodel\u001b[49m\u001b[38;5;241;43m.\u001b[39;49m\u001b[43mpredict\u001b[49m\u001b[43m(\u001b[49m\u001b[43m[\u001b[49m\u001b[43mprepare\u001b[49m\u001b[43m(\u001b[49m\u001b[38;5;124;43m'\u001b[39;49m\u001b[38;5;124;43mCat.jpg\u001b[39;49m\u001b[38;5;124;43m'\u001b[39;49m\u001b[43m)\u001b[49m\u001b[43m]\u001b[49m\u001b[43m)\u001b[49m\n\u001b[0;32m      2\u001b[0m \u001b[38;5;28mprint\u001b[39m(CATEGORIES[\u001b[38;5;28mint\u001b[39m(prediction[\u001b[38;5;241m0\u001b[39m][\u001b[38;5;241m0\u001b[39m])])\n",
      "File \u001b[1;32m~\\anaconda3\\envs\\CleanMLEnv\\lib\\site-packages\\keras\\utils\\traceback_utils.py:70\u001b[0m, in \u001b[0;36mfilter_traceback.<locals>.error_handler\u001b[1;34m(*args, **kwargs)\u001b[0m\n\u001b[0;32m     67\u001b[0m     filtered_tb \u001b[38;5;241m=\u001b[39m _process_traceback_frames(e\u001b[38;5;241m.\u001b[39m__traceback__)\n\u001b[0;32m     68\u001b[0m     \u001b[38;5;66;03m# To get the full stack trace, call:\u001b[39;00m\n\u001b[0;32m     69\u001b[0m     \u001b[38;5;66;03m# `tf.debugging.disable_traceback_filtering()`\u001b[39;00m\n\u001b[1;32m---> 70\u001b[0m     \u001b[38;5;28;01mraise\u001b[39;00m e\u001b[38;5;241m.\u001b[39mwith_traceback(filtered_tb) \u001b[38;5;28;01mfrom\u001b[39;00m \u001b[38;5;28;01mNone\u001b[39;00m\n\u001b[0;32m     71\u001b[0m \u001b[38;5;28;01mfinally\u001b[39;00m:\n\u001b[0;32m     72\u001b[0m     \u001b[38;5;28;01mdel\u001b[39;00m filtered_tb\n",
      "File \u001b[1;32m~\\AppData\\Local\\Temp\\__autograph_generated_filer9s2soeq.py:15\u001b[0m, in \u001b[0;36mouter_factory.<locals>.inner_factory.<locals>.tf__predict_function\u001b[1;34m(iterator)\u001b[0m\n\u001b[0;32m     13\u001b[0m \u001b[38;5;28;01mtry\u001b[39;00m:\n\u001b[0;32m     14\u001b[0m     do_return \u001b[38;5;241m=\u001b[39m \u001b[38;5;28;01mTrue\u001b[39;00m\n\u001b[1;32m---> 15\u001b[0m     retval_ \u001b[38;5;241m=\u001b[39m ag__\u001b[38;5;241m.\u001b[39mconverted_call(ag__\u001b[38;5;241m.\u001b[39mld(step_function), (ag__\u001b[38;5;241m.\u001b[39mld(\u001b[38;5;28mself\u001b[39m), ag__\u001b[38;5;241m.\u001b[39mld(iterator)), \u001b[38;5;28;01mNone\u001b[39;00m, fscope)\n\u001b[0;32m     16\u001b[0m \u001b[38;5;28;01mexcept\u001b[39;00m:\n\u001b[0;32m     17\u001b[0m     do_return \u001b[38;5;241m=\u001b[39m \u001b[38;5;28;01mFalse\u001b[39;00m\n",
      "\u001b[1;31mValueError\u001b[0m: in user code:\n\n    File \"C:\\Users\\oscar\\anaconda3\\envs\\CleanMLEnv\\lib\\site-packages\\keras\\engine\\training.py\", line 2041, in predict_function  *\n        return step_function(self, iterator)\n    File \"C:\\Users\\oscar\\anaconda3\\envs\\CleanMLEnv\\lib\\site-packages\\keras\\engine\\training.py\", line 2027, in step_function  **\n        outputs = model.distribute_strategy.run(run_step, args=(data,))\n    File \"C:\\Users\\oscar\\anaconda3\\envs\\CleanMLEnv\\lib\\site-packages\\keras\\engine\\training.py\", line 2015, in run_step  **\n        outputs = model.predict_step(data)\n    File \"C:\\Users\\oscar\\anaconda3\\envs\\CleanMLEnv\\lib\\site-packages\\keras\\engine\\training.py\", line 1983, in predict_step\n        return self(x, training=False)\n    File \"C:\\Users\\oscar\\anaconda3\\envs\\CleanMLEnv\\lib\\site-packages\\keras\\utils\\traceback_utils.py\", line 70, in error_handler\n        raise e.with_traceback(filtered_tb) from None\n    File \"C:\\Users\\oscar\\anaconda3\\envs\\CleanMLEnv\\lib\\site-packages\\keras\\engine\\input_spec.py\", line 295, in assert_input_compatibility\n        raise ValueError(\n\n    ValueError: Input 0 of layer \"sequential_27\" is incompatible with the layer: expected shape=(None, 70, 70, 1), found shape=(None, 100, 100, 1)\n"
     ]
    }
   ],
   "source": [
    "prediction = model.predict([prepare('Cat.jpg')])\n",
    "print(CATEGORIES[int(prediction[0][0])])"
   ]
  },
  {
   "cell_type": "code",
   "execution_count": 5,
   "id": "00de8d61-8a57-4cc3-8905-195644c09653",
   "metadata": {},
   "outputs": [
    {
     "name": "stdout",
     "output_type": "stream",
     "text": [
      "1/1 [==============================] - 0s 22ms/step\n",
      "Dog\n"
     ]
    }
   ],
   "source": [
    "prediction = model.predict([prepare('Cat2.jpg')])\n",
    "print(CATEGORIES[int(prediction[0][0])])"
   ]
  },
  {
   "cell_type": "code",
   "execution_count": 4,
   "id": "02e1df1f-4bf7-4314-9b3d-6a257c9a024d",
   "metadata": {},
   "outputs": [
    {
     "name": "stdout",
     "output_type": "stream",
     "text": [
      "1/1 [==============================] - 0s 21ms/step\n",
      "Dog\n"
     ]
    }
   ],
   "source": [
    "prediction = model.predict([prepare('Dog.jpg')])\n",
    "print(CATEGORIES[int(prediction[0][0])])"
   ]
  }
 ],
 "metadata": {
  "kernelspec": {
   "display_name": "Python (Clean ML)",
   "language": "python",
   "name": "cleanmlenv"
  },
  "language_info": {
   "codemirror_mode": {
    "name": "ipython",
    "version": 3
   },
   "file_extension": ".py",
   "mimetype": "text/x-python",
   "name": "python",
   "nbconvert_exporter": "python",
   "pygments_lexer": "ipython3",
   "version": "3.10.13"
  }
 },
 "nbformat": 4,
 "nbformat_minor": 5
}
